Workbook

Sheet Grupo Avanza SPA
A1: Libro: Remuneraciones
A2: Empresa: Grupo Avanza SPA (76.008.458-1)
A3: Periodo: Agosto 2026
A4: Fecha Generación: 28/08/2026 a las 02:47PM
A5: 1 | B5: 2 | C5: 3 | D5: 4 | E5: 5 | F5: 6 | G5: 7 | H5: 8 | I5: 9 | J5: 10 | K5: 11 | L5: 12 | M5: 13 | N5: 14 | O5: 15 | P5: 16 | Q5: 17 | R5: 18 | S5: 19 | T5: 20 | U5: 21 | V5: 22 | W5: 23 | X5: 24 | Y5: 25 | Z5: 26 | AA5: 27 | AB5: 28 | AC5: 29 | AD5: 30 | AE5: 31 | AF5: 32 | AG5: 33 | AH5: 34 | AI5: 35 | AJ5: 36 | AK5: 37 | AL5: 38 | AM5: 39 | AN5: 40 | AO5: 41 | AP5: 42 | AQ5: 43 | AR5: 44 | AS5: 45 | AT5: 46 | AU5: 47 | AV5: 48 | AW5: 49 | AX5: 50
A6: RUT | B6: CÓDIGO | C6: AP PATERNO | D6: AP MATERNO | E6: NOMBRES | F6: CARGO | G6: AREA | H6: CENTRO COSTO | I6: DÍAS TRABAJADOS | J6: HORAS SEMANALES | K6: HORAS NO TRABAJADAS | L6: BASE IMP. PREVISIÓN | M6: BASE IMP. CESANTÍA | N6: SUELDO BASE | O6: GRATIFICACIÓN | P6: APORTE ASISTENCIA | Q6: HORAS EXTRAS | R6: ASIGNACIÓN FAMILIAR | S6: ASIGNACIÓN POR TELETRABAJO | T6: ASIGNACIÓN SALA CUNA | U6: ASIGNACIÓN TELEFONÍA E INTERNET | V6: BONO | W6: BONO ESTUDIO | X6: BONO GESTIÓN | Y6: BONO INTERNET | Z6: BONO TELEFONIA | AA6: BONO TRIMESTRAL ACUERDO MARCO | AB6: COLACIÓN | AC6: COMISIONES | AD6: DIFERENCIA BONO | AE6: INCENTIVO TRIMESTRAL CUOTA 3 | AF6: MOVILIZACIÓN | AG6: VIATICO | AH6: TOTAL HABERES | AI6: PREVIS | AJ6: APV | AK6: SALUD | AL6: SALUD VOLUNTARIA | AM6: CESANTÍA | AN6: IMPUESTO | AO6: CUENTA_2 | AP6: ANTICIPO DE REMUNERACIONES | AQ6: CONVENIO FALP | AR6: CUENTA 2 PESOS | AS6: CRÉDITO PERSONAL CAJA LOS ANDES | AT6: PRESTAMO EMPRESA | AU6: PRÉSTAMO EMPRESA | AV6: SEGURO DE VIDA CAJA LOS ANDES | AW6: TOTAL DESCUENTOS | AX6: SUELDO LÍQUIDO | AY6: SOBREGIRO
A7: 16.280.871-0 | B7: F1 | C7: Aguirre | D7: Vásquez | E7: Stefania Alejandra | F7: Coordinador Senior de Cultura y Desarrollo | G7: OUTSOURCING, Codelco Casa Matriz, Codelco Casa Matriz | I7: 30 | J7: 40 | K7: 0 | L7: 2489778 | M7: 2489778 | N7: 1797330 | O7: 219115 | P7: 0 | Q7: 0 | R7: 0 | Y7: 30000 | AA7: 473333 | AB7: 130000 | AF7: 100000 | AH7: 2749778 | AI7: 280598 | AJ7: 0 | AK7: 174284 | AL7: 0 | AM7: 14939 | AN7: 42108 | AO7: 0 | AW7: 511929 | AX7: 2237849 | AY7: =VLOOKUP(A7,'Hoja 1'!A:AX,50,0)-AX7 -> 0
A8: 17.858.538-k | B8: F1 | C8: Alucema | D8: Moraga | E8: Lucía Beatriz | F8: PSICOLOGA | G8: OUTSOURCING, Cia. Minera del Pacifico S.A., Cia. Minera del Pacifico S.A. | H8: 100 | I8: 0 | J8: 40 | K8: 0 | L8: 0 | M8: 0 | N8: 0 | O8: 0 | P8: 0 | Q8: 0 | R8: 0 | AB8: 0 | AF8: 0 | AH8: 0 | AI8: 0 | AJ8: 0 | AK8: 0 | AL8: 0 | AM8: 0 | AN8: 0 | AO8: 0 | AW8: 0 | AX8: 0 | AY8: =VLOOKUP(A8,'Hoja 1'!A:AX,50,0)-AX8 -> 0
A9: 20.231.495-3 | B9: F1 | C9: Aravena | D9: Rodriguez | E9: Claudia Valentina | F9: Coordinador de Cultura y Desarrollo | G9: OUTSOURCING, Codelco Casa Matriz, Codelco Casa Matriz | I9: 30 | J9: 40 | K9: 0 | L9: 2002961 | M9: 2002961 | N9: 1310513 | O9: 219115 | P9: 0 | Q9: 0 | R9: 0 | Y9: 75000 | AA9: 473333 | AB9: 150000 | AF9: 75000 | AH9: 2302961 | AI9: 209510 | AJ9: 5000 | AK9: 140207 | AL9: 0 | AM9: 12018 | AN9: 26959 | AO9: 0 | AR9: 65000 | AW9: 458694 | AX9: 1844267 | AY9: =VLOOKUP(A9,'Hoja 1'!A:AX,50,0)-AX9 -> 0
A10: 18.354.198-6 | B10: F1 | C10: Araya | D10: Cortés | E10: Eduardo Antonio | F10: Programador | G10: Over Head, IT, IT | H10: 100 | I10: 30 | J10: 42 | K10: 0 | L10: 1025146 | M10: 1025146 | N10: 820117 | O10: 205029 | P10: 0 | Q10: 0 | R10: 0 | AB10: 90000 | AF10: 90000 | AH10: 1205146 | AI10: 108460 | AJ10: 0 | AK10: 71760 | AL10: 0 | AM10: 6151 | AN10: 0 | AO10: 0 | AW10: 186371 | AX10: 1018775 | AY10: =VLOOKUP(A10,'Hoja 1'!A:AX,50,0)-AX10 -> 0
A11: 14.027.919-6 | B11: F1 | C11: Bawarshi | D11: Abarzua | E11: Alfonso Ignacio | F11: Director Ejecutivo | G11: Over Head, Administración, Comercial | H11: 1111 | I11: 30 | J11: 44 | K11: 0 | L11: 3678639 | M11: 5526134 | N11: 12365703 | O11: 219115 | P11: 0 | Q11: 0 | R11: 0 | AH11: 12584818 | AI11: 420836 | AJ11: 0 | AK11: 257505 | AL11: 125278 | AM11: 0 | AN11: 2496412 | AO11: 0 | AW11: 3300031 | AX11: 9284787 | AY11: =VLOOKUP(A11,'Hoja 1'!A:AX,50,0)-AX11 -> 0
A12: 17.408.142-5 | B12: F1 | C12: Bawarshi | D12: Abarzua | E12: Gabriela Estefania | F12: Analista Senior DO | G12: Over Head, Administración, Comercial | H12: 1111 | I12: 30 | J12: 42 | K12: 0 | L12: 861875 | M12: 861875 | N12: 689500 | O12: 172375 | P12: 0 | Q12: 0 | R12: 0 | AH12: 861875 | AI12: 96185 | AJ12: 0 | AK12: 60331 | AL12: 156136 | AM12: 5171 | AN12: 0 | AO12: 0 | AW12: 317823 | AX12: 544052 | AY12: =VLOOKUP(A12,'Hoja 1'!A:AX,50,0)-AX12 -> 0
A13: 22.074.650-k | B13: F1 | C13: Bustiman | D13: Gonzalez | E13: Gabriel Bastian | F13: Technician Service Assistance | G13: OUTSOURCING, Endress Hauser, Endress Hauser | H13: 100 | I13: 30 | J13: 44 | K13: 0 | L13: 800000 | M13: 800000 | N13: 640000 | O13: 160000 | P13: 0 | Q13: 0 | R13: 0 | AH13: 800000 | AI13: 83680 | AJ13: 0 | AK13: 56000 | AL13: 0 | AM13: 4800 | AN13: 0 | AO13: 0 | AW13: 144480 | AX13: 655520 | AY13: =VLOOKUP(A13,'Hoja 1'!A:AX,50,0)-AX13 -> 0
A14: 28.830.860-8 | B14: F1 | C14: Camacho | D14: Cordero | E14: Roger Alberto | F14: Gestor de Procesos | G14: OUTSOURCING, Goldfields, Goldfield | H14: 100 | I14: 30 | J14: 40 | K14: 0 | L14: 2500533 | M14: 2500533 | N14: 2281418 | O14: 219115 | P14: 0 | Q14: 0 | R14: 0 | AH14: 2500533 | AI14: 261556 | AJ14: 0 | AK14: 175037 | AL14: 55328 | AM14: 0 | AN14: 41654 | AO14: 0 | AW14: 533575 | AX14: 1966958 | AY14: =VLOOKUP(A14,'Hoja 1'!A:AX,50,0)-AX14 -> 0
A15: 20.043.827-2 | B15: F1 | C15: Cantarero | D15: Pacheco | E15: Elias Matias Ignacio | F15: SERVICE TECHNICIAL | G15: OUTSOURCING, Endress Hauser, Endress Hauser | H15: 100 | I15: 30 | J15: 42 | K15: 0 | L15: 1356403 | M15: 1356403 | N15: 1137288 | O15: 219115 | P15: 0 | Q15: 0 | R15: 0 | AH15: 1356403 | AI15: 143507 | AJ15: 0 | AK15: 94948 | AL15: 0 | AM15: 8138 | AN15: 5702 | AO15: 0 | AW15: 252295 | AX15: 1104108 | AY15: =VLOOKUP(A15,'Hoja 1'!A:AX,50,0)-AX15 -> 0
A16: 20.411.355-6 | B16: F1 | C16: Carreño | D16: Espinoza | E16: Amaranta Paola | F16: Asistente de Gestion de Personas | G16: OUTSOURCING, Cia. Minera del Pacifico S.A., Cia. Minera del Pacifico S.A. | H16: 100 | I16: 29 | J16: 40 | K16: 0 | L16: 1283580 | M16: 1283580 | N16: 1064465 | O16: 219115 | P16: 0 | Q16: 0 | R16: 0 | T16: 350000 | AB16: 43500 | AF16: 43500 | AH16: 1720580 | AI16: 135803 | AJ16: 0 | AK16: 89851 | AL16: 0 | AM16: 7701 | AN16: 3319 | AO16: 0 | AW16: 236674 | AX16: 1483906 | AY16: =VLOOKUP(A16,'Hoja 1'!A:AX,50,0)-AX16 -> -350000
A17: 21.380.747-1 | B17: F1 | C17: Catalan | D17: Mardones | E17: Javiera Alejandra | F17: Asistente Contable | G17: OUTSOURCING, CONTINENTAL SEGUROS, CONTINENTAL SEGUROS | H17: 100 | I17: 30 | J17: 42 | K17: 0 | L17: 847959 | M17: 847959 | N17: 678367 | O17: 169592 | P17: 0 | Q17: 0 | R17: 0 | AB17: 90000 | AF17: 90000 | AH17: 1027959 | AI17: 89714 | AJ17: 0 | AK17: 59357 | AL17: 0 | AM17: 5088 | AN17: 0 | AO17: 0 | AW17: 154159 | AX17: 873800 | AY17: =VLOOKUP(A17,'Hoja 1'!A:AX,50,0)-AX17 -> 0
A18: 19.135.138-k | B18: F1 | C18: Cataldo | D18: Caviedes | E18: Claudia Fernanda | F18: Coordinador de Reclutamiento y Selección | G18: Hunting, Hunting, Hunting | H18: 1111 | I18: 30 | J18: 42 | K18: 0 | L18: 1758961 | M18: 1758961 | N18: 1539846 | O18: 219115 | P18: 0 | Q18: 0 | R18: 0 | AB18: 100000 | AF18: 100000 | AH18: 1958961 | AI18: 186098 | AJ18: 0 | AK18: 123127 | AL18: 1865 | AM18: 10554 | AN18: 18802 | AO18: 0 | AQ18: 19800 | AW18: 360246 | AX18: 1598715 | AY18: =VLOOKUP(A18,'Hoja 1'!A:AX,50,0)-AX18 -> 0
A19: 19.867.384-6 | B19: F1 | C19: Caul | D19: Cortes | E19: Francisca Valentina | F19: Coordinador Avanzado | G19: OUTSOURCING, CODELCO CHILE -V. P., CODELCO CHILE -V. P. | H19: 100 | I19: 30 | J19: 40 | K19: 0 | L19: 2018709 | M19: 2018709 | N19: 1484039 | O19: 219115 | P19: 0 | Q19: 0 | R19: 0 | AB19: 100000 | AE19: 315555 | AF19: 100000 | AH19: 2218709 | AI19: 213579 | AJ19: 0 | AK19: 141310 | AL19: 0 | AM19: 12112 | AN19: 27378 | AO19: 0 | AW19: 394379 | AX19: 1824330 | AY19: =VLOOKUP(A19,'Hoja 1'!A:AX,50,0)-AX19 -> 0
A20: 16.479.434-2 | B20: F1 | C20: Correa | D20: Araya | E20: Camila Denis | F20: KEY ACCOUNT MANAGER SENIOR | G20: Over Head, Administración, Comercial | H20: 1111 | I20: 30 | J20: 42 | K20: 0 | L20: 2071498 | M20: 2071498 | N20: 1852383 | O20: 219115 | P20: 0 | Q20: 0 | R20: 0 | AB20: 80000 | AF20: 80000 | AH20: 2231498 | AI20: 233458 | AJ20: 0 | AK20: 145005 | AL20: 42933 | AM20: 12429 | AN20: 26816 | AO20: 0 | AW20: 460641 | AX20: 1770857 | AY20: =VLOOKUP(A20,'Hoja 1'!A:AX,50,0)-AX20 -> 0
A21: 26.972.625-3 | B21: F1 | C21: De Sousa | D21: Garcia | E21: Stephen William | F21: Control Interno | G21: OUTSOURCING, Goldfields, Goldfield | H21: 100 | I21: 30 | J21: 42 | K21: 0 | L21: 2279115 | M21: 2279115 | N21: 2060000 | O21: 219115 | P21: 0 | Q21: 0 | R21: 0 | AB21: 100000 | AF21: 100000 | AH21: 2479115 | AI21: 238395 | AJ21: 0 | AK21: 159538 | AL21: 89138 | AM21: 13675 | AN21: 32444 | AO21: 0 | AP21: 100000 | AW21: 633190 | AX21: 1845925 | AY21: =VLOOKUP(A21,'Hoja 1'!A:AX,50,0)-AX21 -> 0
A22: 26.304.359-6 | B22: F1 | C22: Diaz | D22: Gonzalez | E22: Fatima | F22: Supervisor Técnico del Servicio | G22: OUTSOURCING, Enap, Enap | H22: 100 | I22: 30 | J22: 37 | K22: 0 | L22: 2816897 | M22: 2816897 | N22: 2597782 | O22: 219115 | P22: 0 | Q22: 0 | R22: 0 | AB22: 280000 | AF22: 280000 | AH22: 3376897 | AI22: 314366 | AJ22: 0 | AK22: 197183 | AL22: 37473 | AM22: 16901 | AN22: 55409 | AO22: 0 | AW22: 621332 | AX22: 2755565 | AY22: =VLOOKUP(A22,'Hoja 1'!A:AX,50,0)-AX22 -> 0
A23: 17.318.383-6 | B23: F1 | C23: Espinoza | D23: Latorre | E23: Daniela Paz Loreto | F23: Especialista en Biodiversidad | G23: OUTSOURCING, Salar Blanco, Salar Blanco | H23: 100 | I23: 22 | J23: 42 | K23: 0 | L23: 3581244 | M23: 3581244 | N23: 3362129 | O23: 219115 | P23: 0 | Q23: 0 | R23: 0 | AH23: 3581244 | AI23: 409694 | AJ23: 0 | AK23: 250687 | AL23: 0 | AM23: 21487 | AN23: 107281 | AO23: 0 | AW23: 789149 | AX23: 2792095 | AY23: =VLOOKUP(A23,'Hoja 1'!A:AX,50,0)-AX23 -> 0
A24: 25.387.977-7 | B24: F1 | C24: Fuentes | D24: Rodriguez | E24: Levy Johan | F24: Especialista Modelamiento | G24: OUTSOURCING, Salar Blanco, Salar Blanco | H24: 100 | I24: 30 | J24: 42 | K24: 0 | L24: 3678639 | M24: 5273749 | N24: 4958453 | O24: 219115 | P24: 0 | Q24: 0 | R24: 0 | AD24: 96181 | AH24: 5273749 | AI24: 420836 | AJ24: 0 | AK24: 257505 | AL24: 74063 | AM24: 0 | AN24: 298676 | AO24: 0 | AW24: 1051080 | AX24: 4222669 | AY24: =VLOOKUP(A24,'Hoja 1'!A:AX,50,0)-AX24 -> 0
A25: 18.585.098-6 | B25: F1 | C25: Garcia | D25: Cruz | E25: Isabel Ivania | F25: Coordinador Senior | G25: OUTSOURCING, CODELCO CHILE -V. P., CODELCO CHILE -V. P. | H25: 100 | I25: 30 | J25: 40 | K25: 0 | L25: 3678639 | M25: 3696162 | N25: 3003714 | O25: 219115 | P25: 0 | Q25: 0 | R25: 0 | AB25: 100000 | AE25: 473333 | AF25: 100000 | AH25: 3896162 | AI25: 414583 | AJ25: 0 | AK25: 257505 | AL25: 0 | AM25: 22177 | AN25: 115482 | AO25: 0 | AQ25: 19800 | AW25: 829547 | AX25: 3066615 | AY25: =VLOOKUP(A25,'Hoja 1'!A:AX,50,0)-AX25 -> 0
A26: 21.166.392-8 | B26: F1 | C26: Garcia | D26: Soria | E26: Alexis Joshua | F26: Especialista en Sistemas | G26: OUTSOURCING, Enap, Enap | H26: 100 | I26: 30 | J26: 37 | K26: 0 | L26: 2399470 | M26: 2399470 | N26: 2180355 | O26: 219115 | P26: 0 | Q26: 0 | R26: 0 | AB26: 250000 | AF26: 250000 | AH26: 2899470 | AI26: 250985 | AJ26: 0 | AK26: 167963 | AL26: 0 | AM26: 14397 | AN26: 39955 | AO26: 0 | AW26: 473300 | AX26: 2426170 | AY26: =VLOOKUP(A26,'Hoja 1'!A:AX,50,0)-AX26 -> 0
A27: 17.852.693-6 | B27: F1 | C27: Gil | D27: Salazar | E27: Ivan Ignacio | F27: SERVICE TECHNICIAL | G27: OUTSOURCING, Endress Hauser, Endress Hauser | H27: 100 | I27: 30 | J27: 42 | K27: 0 | L27: 1356403 | M27: 1356403 | N27: 1137288 | O27: 219115 | P27: 0 | Q27: 0 | R27: 0 | AH27: 1356403 | AI27: 143507 | AJ27: 0 | AK27: 94948 | AL27: 0 | AM27: 8138 | AN27: 5702 | AO27: 0 | AW27: 252295 | AX27: 1104108 | AY27: =VLOOKUP(A27,'Hoja 1'!A:AX,50,0)-AX27 -> 0
A28: 18.668.865-1 | B28: F1 | C28: Gomez | D28: Paris | E28: Rodrigo Ignacio | F28: Coordinador Senior de Cultura y Desarrollo | G28: OUTSOURCING, Codelco Casa Matriz, Codelco Casa Matriz | I28: 30 | J28: 40 | K28: 0 | L28: 2534485 | M28: 2534485 | N28: 1684259 | O28: 219115 | P28: 0 | Q28: 0 | R28: 0 | Y28: 30000 | AA28: 631111 | AB28: 170000 | AF28: 170000 | AH28: 2904485 | AI28: 268149 | AJ28: 0 | AK28: 177414 | AL28: 0 | AM28: 15207 | AN28: 44258 | AO28: 0 | AW28: 505028 | AX28: 2399457 | AY28: =VLOOKUP(A28,'Hoja 1'!A:AX,50,0)-AX28 -> 0
A29: 15.934.450-9 | B29: F1 | C29: Gonzalez | D29: Muñoz | E29: Viviana Soledad | F29: Gerente Comercial | G29: Over Head, Administración, Comercial | H29: 1111 | I29: 30 | J29: 44 | K29: 0 | L29: 3678639 | M29: 3953939 | N29: 3734824 | O29: 219115 | P29: 0 | Q29: 0 | R29: 0 | T29: 600000 | AB29: 200000 | AF29: 200000 | AH29: 4953939 | AI29: 420836 | AJ29: 0 | AK29: 257505 | AL29: 129079 | AM29: 23724 | AN29: 135481 | AO29: 0 | AQ29: 19800 | AW29: 986425 | AX29: 3967514 | AY29: =VLOOKUP(A29,'Hoja 1'!A:AX,50,0)-AX29 -> 0
A30: 19.928.652-8 | B30: F1 | C30: Guerrero | D30: Maldonado | E30: Geraldine | F30: Coordinadora Avanzada | G30: OUTSOURCING, CODELCO CHILE -V. P., CODELCO CHILE -V. P. | H30: 100 | I30: 30 | J30: 40 | K30: 0 | L30: 2176352 | M30: 2176352 | N30: 1483904 | O30: 219115 | P30: 0 | Q30: 0 | R30: 0 | AB30: 100000 | AE30: 473333 | AF30: 100000 | AH30: 2376352 | AI30: 227646 | AJ30: 0 | AK30: 152345 | AL30: 0 | AM30: 13058 | AN30: 32642 | AO30: 0 | AW30: 425691 | AX30: 1950661 | AY30: =VLOOKUP(A30,'Hoja 1'!A:AX,50,0)-AX30 -> 0
A31: 16.477.999-8 | B31: F1 | C31: Gutiérrez | D31: Castro | E31: Carolina Arlette | F31: Analista de Logística JR | G31: OUTSOURCING, Tesa Tape Chile S.A., Tesa Tape Chile S.A. | H31: 100 | I31: 30 | J31: 42 | K31: 0 | L31: 1596165 | M31: 1596165 | N31: 1358500 | O31: 219115 | P31: 0 | Q31: 0 | R31: 0 | V31: 18550 | AH31: 1596165 | AI31: 182601 | AJ31: 0 | AK31: 111732 | AL31: 0 | AM31: 9577 | AN31: 13000 | AO31: 0 | AW31: 316910 | AX31: 1279255 | AY31: =VLOOKUP(A31,'Hoja 1'!A:AX,50,0)-AX31 -> 0
A32: 15.737.550-4 | B32: F1 | C32: Hurtado | D32: Canto | E32: Alejandro Eduardo | F32: Coordinador Senior | G32: OUTSOURCING, CODELCO CHILE -V. P., CODELCO CHILE -V. P. | H32: 100 | I32: 30 | J32: 42 | K32: 0 | L32: 3351652 | M32: 3351652 | N32: 2816982 | O32: 219115 | P32: 0 | Q32: 0 | R32: 0 | AB32: 100000 | AE32: 315555 | AF32: 100000 | AH32: 3551652 | AI32: 377731 | AJ32: 0 | AK32: 234616 | AL32: 16921 | AM32: 20110 | AN32: 91513 | AO32: 0 | AS32: 385837 | AW32: 1126728 | AX32: 2424924 | AY32: =VLOOKUP(A32,'Hoja 1'!A:AX,50,0)-AX32 -> 0
A33: 18.467.232-4 | B33: F1 | C33: Jamis | D33: Matus | E33: Juan Ignacio | F33: Gerente de Clientes y Licitaciones | G33: Over Head, Administración, Comercial | H33: 1111 | I33: 30 | J33: 44 | K33: 0 | L33: 2860189 | M33: 2860189 | N33: 2641074 | O33: 219115 | P33: 0 | Q33: 0 | R33: 0 | AB33: 150000 | AF33: 150000 | AH33: 3160189 | AI33: 302608 | AJ33: 0 | AK33: 200213 | AL33: 0 | AM33: 17161 | AN33: 62547 | AO33: 0 | AQ33: 19800 | AW33: 602329 | AX33: 2557860 | AY33: =VLOOKUP(A33,'Hoja 1'!A:AX,50,0)-AX33 -> 0
A34: 15.805.887-1 | B34: F1 | C34: Jara | D34: Ochoa | E34: Jacqueline Carolina | F34: Asesor Senior de Prevención de Riesgos | G34: OUTSOURCING, CODELCO, Modulo 2 | I34: 30 | J34: 42 | K34: 0 | L34: 2748807 | M34: 2748807 | N34: 2056359 | O34: 219115 | P34: 0 | Q34: 0 | R34: 0 | Y34: 125000 | AA34: 473333 | AB34: 250000 | AF34: 250000 | AH34: 3373807 | AI34: 309791 | AJ34: 0 | AK34: 192416 | AL34: 1080 | AM34: 16493 | AN34: 53653 | AO34: 0 | AS34: 186081 | AW34: 759514 | AX34: 2614293 | AY34: =VLOOKUP(A34,'Hoja 1'!A:AX,50,0)-AX34 -> 0
A35: 13.462.122-2 | B35: F1 | C35: Labraña | D35: Gutierrez | E35: Maria Carolina | F35: Coordinador Experto | G35: OUTSOURCING, CODELCO CHILE -V. P., CODELCO CHILE -V. P. | H35: 100 | I35: 30 | J35: 42 | K35: 0 | L35: 3678639 | M35: 4263081 | N35: 3570633 | O35: 219115 | P35: 0 | Q35: 0 | R35: 0 | AB35: 100000 | AE35: 473333 | AF35: 100000 | AH35: 4463081 | AI35: 414583 | AJ35: 0 | AK35: 257505 | AL35: 1471 | AM35: 25578 | AN35: 160564 | AO35: 0 | AS35: 29854 | AW35: 889555 | AX35: 3573526 | AY35: =VLOOKUP(A35,'Hoja 1'!A:AX,50,0)-AX35 -> 0
A36: 13.035.195-6 | B36: F1 | C36: La Roche | D36: Benitez | E36: Udo Franz | F36: ASSET OPTIMIZATION | G36: OUTSOURCING, Goldfields, Goldfield | H36: 100 | I36: 30 | J36: 40 | K36: 0 | L36: 3678639 | M36: 4328779 | N36: 4109664 | O36: 219115 | P36: 0 | Q36: 0 | R36: 0 | AH36: 4328779 | AI36: 414583 | AJ36: 0 | AK36: 257505 | AL36: 306471 | AM36: 25973 | AN36: 168443 | AO36: 0 | AW36: 1172975 | AX36: 3155804 | AY36: =VLOOKUP(A36,'Hoja 1'!A:AX,50,0)-AX36 -> 0
A37: 20.465.683-5 | B37: F1 | C37: Morales | D37: Valdes | E37: Barbara Jesus | F37: Marketing Analyst | G37: OUTSOURCING, EDGEWELL CHILE, EDGEWELL CHILE | H37: 100 | I37: 21 | J37: 40 | K37: 0 | L37: 1615615 | M37: 1615615 | N37: 1396500 | O37: 219115 | P37: 0 | Q37: 0 | R37: 0 | S37: 7000 | U37: 14000 | AH37: 1636615 | AI37: 170932 | AJ37: 0 | AK37: 113093 | AL37: 21839 | AM37: 9694 | AN37: 13312 | AO37: 0 | AW37: 328870 | AX37: 1307745 | AY37: =VLOOKUP(A37,'Hoja 1'!A:AX,50,0)-AX37 -> 0
A38: 16.163.207-4 | B38: F1 | C38: Morrison | D38: Robles | E38: Dawn Faye | F38: Asistente Comercial Bilingue | G38: Over Head, Administración, Comercial | H38: 1111 | I38: 30 | J38: 44 | K38: 0 | L38: 2586937 | M38: 2586937 | N38: 2367822 | O38: 219115 | P38: 0 | Q38: 0 | R38: 0 | AH38: 2586937 | AI38: 288702 | AJ38: 0 | AK38: 181086 | AL38: 408028 | AM38: 15522 | AN38: 42318 | AO38: 0 | AW38: 935656 | AX38: 1651281 | AY38: =VLOOKUP(A38,'Hoja 1'!A:AX,50,0)-AX38 -> 0
A39: 15.475.910-7 | B39: F1 | C39: Muñoz | D39: Gonzalez | E39: Jocelyn Andrea | F39: Receptionist & Administrative Assistant | G39: OUTSOURCING, Endress Hauser, Endress Hauser | H39: 100 | I39: 3 | J39: 40 | K39: 0 | L39: 183941 | M39: 183941 | N39: 147153 | O39: 36788 | P39: 0 | Q39: 0 | R39: 0 | AH39: 183941 | AI39: 21043 | AJ39: 0 | AK39: 12876 | AL39: 0 | AM39: 1104 | AN39: 0 | AO39: 0 | AQ39: 29700 | AW39: 64723 | AX39: 119218 | AY39: =VLOOKUP(A39,'Hoja 1'!A:AX,50,0)-AX39 -> 0
A40: 18.057.004-7 | B40: F1 | C40: Muñoz | D40: Matamala | E40: Denisse Ninoska | F40: SERVICE ASSISTANT | G40: OUTSOURCING, Endress Hauser, Endress Hauser | H40: 100 | I40: 30 | J40: 42 | K40: 0 | L40: 1700761 | M40: 1700761 | N40: 1481646 | O40: 219115 | P40: 0 | Q40: 0 | R40: 0 | AH40: 1700761 | AI40: 179941 | AJ40: 0 | AK40: 119053 | AL40: 0 | AM40: 10205 | AN40: 16972 | AO40: 0 | AW40: 326171 | AX40: 1374590 | AY40: =VLOOKUP(A40,'Hoja 1'!A:AX,50,0)-AX40 -> 0
...

Sheet Hoja 1
A1: Libro: Remuneraciones
A2: Empresa: Grupo Avanza SPA (76.008.458-1)
A3: Periodo: Agosto 2026
A4: Fecha Generación: 24/08/2026 a las 07:59PM
A6: RUT | B6: CÓDIGO | C6: AP PATERNO | D6: AP MATERNO | E6: NOMBRES | F6: CARGO | G6: AREA | H6: CENTRO COSTO | I6: DÍAS TRABAJADOS | J6: HORAS SEMANALES | K6: HORAS NO TRABAJADAS | L6: BASE IMP. PREVISIÓN | M6: BASE IMP. CESANTÍA | N6: SUELDO BASE | O6: GRATIFICACIÓN | P6: APORTE ASISTENCIA | Q6: HORAS EXTRAS | R6: ASIGNACIÓN FAMILIAR | S6: ASIGNACIÓN POR TELETRABAJO | T6: ASIGNACIÓN SALA CUNA | U6: ASIGNACIÓN TELEFONÍA E INTERNET | V6: BONO | W6: BONO ESTUDIO | X6: BONO GESTIÓN | Y6: BONO INTERNET | Z6: BONO TELEFONIA | AA6: BONO TRIMESTRAL ACUERDO MARCO | AB6: COLACIÓN | AC6: COMISIONES | AD6: DIFERENCIA BONO | AE6: INCENTIVO TRIMESTRAL CUOTA 3 | AF6: MOVILIZACIÓN | AG6: VIATICO | AH6: TOTAL HABERES | AI6: PREVIS | AJ6: APV | AK6: SALUD | AL6: SALUD VOLUNTARIA | AM6: CESANTÍA | AN6: IMPUESTO | AO6: CUENTA_2 | AP6: ANTICIPO DE REMUNERACIONES | AQ6: CONVENIO FALP | AR6: CUENTA 2 PESOS | AS6: CRÉDITO PERSONAL CAJA LOS ANDES | AT6: PRESTAMO EMPRESA | AU6: PRÉSTAMO EMPRESA | AV6: SEGURO DE VIDA CAJA LOS ANDES | AW6: TOTAL DESCUENTOS | AX6: SUELDO LÍQUIDO | AY6: SOBREGIRO
A7: 16.280.871-0 | B7: F1 | C7: Aguirre | D7: Vásquez | E7: Stefania Alejandra | F7: Coordinador Senior de Cultura y Desarrollo | G7: OUTSOURCING, Codelco Casa Matriz, Codelco Casa Matriz | I7: 30 | J7: 40 | K7: 0 | L7: 2489778 | M7: 2489778 | N7: 1797330 | O7: 219115 | P7: 0 | Q7: 0 | R7: 0 | Y7: 30000 | AA7: 473333 | AB7: 130000 | AF7: 100000 | AH7: 2749778 | AI7: 280598 | AJ7: 0 | AK7: 174284 | AL7: 0 | AM7: 14939 | AN7: 42108 | AO7: 0 | AW7: 511929 | AX7: 2237849 | AY7: 0
A8: 17.858.538-k | B8: F1 | C8: Alucema | D8: Moraga | E8: Lucía Beatriz | F8: PSICOLOGA | G8: OUTSOURCING, Cia. Minera del Pacifico S.A., Cia. Minera del Pacifico S.A. | H8: 100 | I8: 0 | J8: 40 | K8: 0 | L8: 0 | M8: 0 | N8: 0 | O8: 0 | P8: 0 | Q8: 0 | R8: 0 | AB8: 0 | AF8: 0 | AH8: 0 | AI8: 0 | AJ8: 0 | AK8: 0 | AL8: 0 | AM8: 0 | AN8: 0 | AO8: 0 | AW8: 0 | AX8: 0 | AY8: 0
A9: 20.231.495-3 | B9: F1 | C9: Aravena | D9: Rodriguez | E9: Claudia Valentina | F9: Coordinador de Cultura y Desarrollo | G9: OUTSOURCING, Codelco Casa Matriz, Codelco Casa Matriz | I9: 30 | J9: 40 | K9: 0 | L9: 2002961 | M9: 2002961 | N9: 1310513 | O9: 219115 | P9: 0 | Q9: 0 | R9: 0 | Y9: 75000 | AA9: 473333 | AB9: 150000 | AF9: 75000 | AH9: 2302961 | AI9: 209510 | AJ9: 5000 | AK9: 140207 | AL9: 0 | AM9: 12018 | AN9: 26959 | AO9: 0 | AR9: 65000 | AW9: 458694 | AX9: 1844267 | AY9: 0
A10: 18.354.198-6 | B10: F1 | C10: Araya | D10: Cortés | E10: Eduardo Antonio | F10: Programador | G10: Over Head, IT, IT | H10: 100 | I10: 30 | J10: 42 | K10: 0 | L10: 1025146 | M10: 1025146 | N10: 820117 | O10: 205029 | P10: 0 | Q10: 0 | R10: 0 | AB10: 90000 | AF10: 90000 | AH10: 1205146 | AI10: 108460 | AJ10: 0 | AK10: 71760 | AL10: 0 | AM10: 6151 | AN10: 0 | AO10: 0 | AW10: 186371 | AX10: 1018775 | AY10: 0
A11: 14.027.919-6 | B11: F1 | C11: Bawarshi | D11: Abarzua | E11: Alfonso Ignacio | F11: Director Ejecutivo | G11: Over Head, Administración, Comercial | H11: 1111 | I11: 30 | J11: 44 | K11: 0 | L11: 3678639 | M11: 5526134 | N11: 12365703 | O11: 219115 | P11: 0 | Q11: 0 | R11: 0 | AH11: 12584818 | AI11: 420836 | AJ11: 0 | AK11: 257505 | AL11: 125278 | AM11: 0 | AN11: 2496412 | AO11: 0 | AW11: 3300031 | AX11: 9284787 | AY11: 0
A12: 17.408.142-5 | B12: F1 | C12: Bawarshi | D12: Abarzua | E12: Gabriela Estefania | F12: Analista Senior DO | G12: Over Head, Administración, Comercial | H12: 1111 | I12: 30 | J12: 42 | K12: 0 | L12: 861875 | M12: 861875 | N12: 689500 | O12: 172375 | P12: 0 | Q12: 0 | R12: 0 | AH12: 861875 | AI12: 96185 | AJ12: 0 | AK12: 60331 | AL12: 156136 | AM12: 5171 | AN12: 0 | AO12: 0 | AW12: 317823 | AX12: 544052 | AY12: 0
A13: 22.074.650-k | B13: F1 | C13: Bustiman | D13: Gonzalez | E13: Gabriel Bastian | F13: Technician Service Assistance | G13: OUTSOURCING, Endress Hauser, Endress Hauser | H13: 100 | I13: 30 | J13: 44 | K13: 0 | L13: 800000 | M13: 800000 | N13: 640000 | O13: 160000 | P13: 0 | Q13: 0 | R13: 0 | AH13: 800000 | AI13: 83680 | AJ13: 0 | AK13: 56000 | AL13: 0 | AM13: 4800 | AN13: 0 | AO13: 0 | AW13: 144480 | AX13: 655520 | AY13: 0
A14: 28.830.860-8 | B14: F1 | C14: Camacho | D14: Cordero | E14: Roger Alberto | F14: Gestor de Procesos | G14: OUTSOURCING, Goldfields, Goldfield | H14: 100 | I14: 30 | J14: 40 | K14: 0 | L14: 2500533 | M14: 2500533 | N14: 2281418 | O14: 219115 | P14: 0 | Q14: 0 | R14: 0 | AH14: 2500533 | AI14: 261556 | AJ14: 0 | AK14: 175037 | AL14: 55328 | AM14: 0 | AN14: 41654 | AO14: 0 | AW14: 533575 | AX14: 1966958 | AY14: 0
A15: 20.043.827-2 | B15: F1 | C15: Cantarero | D15: Pacheco | E15: Elias Matias Ignacio | F15: SERVICE TECHNICIAL | G15: OUTSOURCING, Endress Hauser, Endress Hauser | H15: 100 | I15: 30 | J15: 42 | K15: 0 | L15: 1356403 | M15: 1356403 | N15: 1137288 | O15: 219115 | P15: 0 | Q15: 0 | R15: 0 | AH15: 1356403 | AI15: 143507 | AJ15: 0 | AK15: 94948 | AL15: 0 | AM15: 8138 | AN15: 5702 | AO15: 0 | AW15: 252295 | AX15: 1104108 | AY15: 0
A16: 20.411.355-6 | B16: F1 | C16: Carreño | D16: Espinoza | E16: Amaranta Paola | F16: Asistente de Gestion de Personas | G16: OUTSOURCING, Cia. Minera del Pacifico S.A., Cia. Minera del Pacifico S.A. | H16: 100 | I16: 29 | J16: 40 | K16: 0 | L16: 1283580 | M16: 1283580 | N16: 1064465 | O16: 219115 | P16: 0 | Q16: 0 | R16: 0 | AB16: 43500 | AF16: 43500 | AH16: 1370580 | AI16: 135803 | AJ16: 0 | AK16: 89851 | AL16: 0 | AM16: 7701 | AN16: 3319 | AO16: 0 | AW16: 236674 | AX16: 1133906 | AY16: 0
A17: 21.380.747-1 | B17: F1 | C17: Catalan | D17: Mardones | E17: Javiera Alejandra | F17: Asistente Contable | G17: OUTSOURCING, CONTINENTAL SEGUROS, CONTINENTAL SEGUROS | H17: 100 | I17: 30 | J17: 42 | K17: 0 | L17: 847959 | M17: 847959 | N17: 678367 | O17: 169592 | P17: 0 | Q17: 0 | R17: 0 | AB17: 90000 | AF17: 90000 | AH17: 1027959 | AI17: 89714 | AJ17: 0 | AK17: 59357 | AL17: 0 | AM17: 5088 | AN17: 0 | AO17: 0 | AW17: 154159 | AX17: 873800 | AY17: 0
A18: 19.135.138-k | B18: F1 | C18: Cataldo | D18: Caviedes | E18: Claudia Fernanda | F18: Coordinador de Reclutamiento y Selección | G18: Hunting, Hunting, Hunting | H18: 1111 | I18: 30 | J18: 42 | K18: 0 | L18: 1758961 | M18: 1758961 | N18: 1539846 | O18: 219115 | P18: 0 | Q18: 0 | R18: 0 | AB18: 100000 | AF18: 100000 | AH18: 1958961 | AI18: 186098 | AJ18: 0 | AK18: 123127 | AL18: 1865 | AM18: 10554 | AN18: 18802 | AO18: 0 | AQ18: 19800 | AW18: 360246 | AX18: 1598715 | AY18: 0
A19: 19.867.384-6 | B19: F1 | C19: Caul | D19: Cortes | E19: Francisca Valentina | F19: Coordinador Avanzado | G19: OUTSOURCING, CODELCO CHILE -V. P., CODELCO CHILE -V. P. | H19: 100 | I19: 30 | J19: 40 | K19: 0 | L19: 2018709 | M19: 2018709 | N19: 1484039 | O19: 219115 | P19: 0 | Q19: 0 | R19: 0 | AB19: 100000 | AE19: 315555 | AF19: 100000 | AH19: 2218709 | AI19: 213579 | AJ19: 0 | AK19: 141310 | AL19: 0 | AM19: 12112 | AN19: 27378 | AO19: 0 | AW19: 394379 | AX19: 1824330 | AY19: 0
A20: 16.479.434-2 | B20: F1 | C20: Correa | D20: Araya | E20: Camila Denis | F20: KEY ACCOUNT MANAGER SENIOR | G20: Over Head, Administración, Comercial | H20: 1111 | I20: 30 | J20: 42 | K20: 0 | L20: 2071498 | M20: 2071498 | N20: 1852383 | O20: 219115 | P20: 0 | Q20: 0 | R20: 0 | AB20: 80000 | AF20: 80000 | AH20: 2231498 | AI20: 233458 | AJ20: 0 | AK20: 145005 | AL20: 42933 | AM20: 12429 | AN20: 26816 | AO20: 0 | AW20: 460641 | AX20: 1770857 | AY20: 0
A21: 26.972.625-3 | B21: F1 | C21: De Sousa | D21: Garcia | E21: Stephen William | F21: Control Interno | G21: OUTSOURCING, Goldfields, Goldfield | H21: 100 | I21: 30 | J21: 42 | K21: 0 | L21: 2279115 | M21: 2279115 | N21: 2060000 | O21: 219115 | P21: 0 | Q21: 0 | R21: 0 | AB21: 100000 | AF21: 100000 | AH21: 2479115 | AI21: 238395 | AJ21: 0 | AK21: 159538 | AL21: 89138 | AM21: 13675 | AN21: 32444 | AO21: 0 | AP21: 100000 | AW21: 633190 | AX21: 1845925 | AY21: 0
A22: 26.304.359-6 | B22: F1 | C22: Diaz | D22: Gonzalez | E22: Fatima | F22: Supervisor Técnico del Servicio | G22: OUTSOURCING, Enap, Enap | H22: 100 | I22: 30 | J22: 37 | K22: 0 | L22: 2816897 | M22: 2816897 | N22: 2597782 | O22: 219115 | P22: 0 | Q22: 0 | R22: 0 | AB22: 280000 | AF22: 280000 | AH22: 3376897 | AI22: 314366 | AJ22: 0 | AK22: 197183 | AL22: 37473 | AM22: 16901 | AN22: 55409 | AO22: 0 | AW22: 621332 | AX22: 2755565 | AY22: 0
A23: 17.318.383-6 | B23: F1 | C23: Espinoza | D23: Latorre | E23: Daniela Paz Loreto | F23: Especialista en Biodiversidad | G23: OUTSOURCING, Salar Blanco, Salar Blanco | H23: 100 | I23: 22 | J23: 42 | K23: 0 | L23: 3581244 | M23: 3581244 | N23: 3362129 | O23: 219115 | P23: 0 | Q23: 0 | R23: 0 | AH23: 3581244 | AI23: 409694 | AJ23: 0 | AK23: 250687 | AL23: 0 | AM23: 21487 | AN23: 107281 | AO23: 0 | AW23: 789149 | AX23: 2792095 | AY23: 0
A24: 25.387.977-7 | B24: F1 | C24: Fuentes | D24: Rodriguez | E24: Levy Johan | F24: Especialista Modelamiento | G24: OUTSOURCING, Salar Blanco, Salar Blanco | H24: 100 | I24: 30 | J24: 42 | K24: 0 | L24: 3678639 | M24: 5273749 | N24: 4958453 | O24: 219115 | P24: 0 | Q24: 0 | R24: 0 | AD24: 96181 | AH24: 5273749 | AI24: 420836 | AJ24: 0 | AK24: 257505 | AL24: 74063 | AM24: 0 | AN24: 298676 | AO24: 0 | AW24: 1051080 | AX24: 4222669 | AY24: 0
A25: 18.585.098-6 | B25: F1 | C25: Garcia | D25: Cruz | E25: Isabel Ivania | F25: Coordinador Senior | G25: OUTSOURCING, CODELCO CHILE -V. P., CODELCO CHILE -V. P. | H25: 100 | I25: 30 | J25: 40 | K25: 0 | L25: 3678639 | M25: 3696162 | N25: 3003714 | O25: 219115 | P25: 0 | Q25: 0 | R25: 0 | AB25: 100000 | AE25: 473333 | AF25: 100000 | AH25: 3896162 | AI25: 414583 | AJ25: 0 | AK25: 257505 | AL25: 0 | AM25: 22177 | AN25: 115482 | AO25: 0 | AQ25: 19800 | AW25: 829547 | AX25: 3066615 | AY25: 0
A26: 21.166.392-8 | B26: F1 | C26: Garcia | D26: Soria | E26: Alexis Joshua | F26: Especialista en Sistemas | G26: OUTSOURCING, Enap, Enap | H26: 100 | I26: 30 | J26: 37 | K26: 0 | L26: 2399470 | M26: 2399470 | N26: 2180355 | O26: 219115 | P26: 0 | Q26: 0 | R26: 0 | AB26: 250000 | AF26: 250000 | AH26: 2899470 | AI26: 250985 | AJ26: 0 | AK26: 167963 | AL26: 0 | AM26: 14397 | AN26: 39955 | AO26: 0 | AW26: 473300 | AX26: 2426170 | AY26: 0
A27: 17.852.693-6 | B27: F1 | C27: Gil | D27: Salazar | E27: Ivan Ignacio | F27: SERVICE TECHNICIAL | G27: OUTSOURCING, Endress Hauser, Endress Hauser | H27: 100 | I27: 30 | J27: 42 | K27: 0 | L27: 1356403 | M27: 1356403 | N27: 1137288 | O27: 219115 | P27: 0 | Q27: 0 | R27: 0 | AH27: 1356403 | AI27: 143507 | AJ27: 0 | AK27: 94948 | AL27: 0 | AM27: 8138 | AN27: 5702 | AO27: 0 | AW27: 252295 | AX27: 1104108 | AY27: 0
A28: 18.668.865-1 | B28: F1 | C28: Gomez | D28: Paris | E28: Rodrigo Ignacio | F28: Coordinador Senior de Cultura y Desarrollo | G28: OUTSOURCING, Codelco Casa Matriz, Codelco Casa Matriz | I28: 30 | J28: 40 | K28: 0 | L28: 2534485 | M28: 2534485 | N28: 1684259 | O28: 219115 | P28: 0 | Q28: 0 | R28: 0 | Y28: 30000 | AA28: 631111 | AB28: 170000 | AF28: 170000 | AH28: 2904485 | AI28: 268149 | AJ28: 0 | AK28: 177414 | AL28: 0 | AM28: 15207 | AN28: 44258 | AO28: 0 | AW28: 505028 | AX28: 2399457 | AY28: 0
A29: 15.934.450-9 | B29: F1 | C29: Gonzalez | D29: Muñoz | E29: Viviana Soledad | F29: Gerente Comercial | G29: Over Head, Administración, Comercial | H29: 1111 | I29: 30 | J29: 44 | K29: 0 | L29: 3678639 | M29: 3953939 | N29: 3734824 | O29: 219115 | P29: 0 | Q29: 0 | R29: 0 | T29: 600000 | AB29: 200000 | AF29: 200000 | AH29: 4953939 | AI29: 420836 | AJ29: 0 | AK29: 257505 | AL29: 129079 | AM29: 23724 | AN29: 135481 | AO29: 0 | AQ29: 19800 | AW29: 986425 | AX29: 3967514 | AY29: 0
A30: 19.928.652-8 | B30: F1 | C30: Guerrero | D30: Maldonado | E30: Geraldine | F30: Coordinadora Avanzada | G30: OUTSOURCING, CODELCO CHILE -V. P., CODELCO CHILE -V. P. | H30: 100 | I30: 30 | J30: 40 | K30: 0 | L30: 2176352 | M30: 2176352 | N30: 1483904 | O30: 219115 | P30: 0 | Q30: 0 | R30: 0 | AB30: 100000 | AE30: 473333 | AF30: 100000 | AH30: 2376352 | AI30: 227646 | AJ30: 0 | AK30: 152345 | AL30: 0 | AM30: 13058 | AN30: 32642 | AO30: 0 | AW30: 425691 | AX30: 1950661 | AY30: 0
A31: 16.477.999-8 | B31: F1 | C31: Gutiérrez | D31: Castro | E31: Carolina Arlette | F31: Analista de Logística JR | G31: OUTSOURCING, Tesa Tape Chile S.A., Tesa Tape Chile S.A. | H31: 100 | I31: 30 | J31: 42 | K31: 0 | L31: 1596165 | M31: 1596165 | N31: 1358500 | O31: 219115 | P31: 0 | Q31: 0 | R31: 0 | V31: 18550 | AH31: 1596165 | AI31: 182601 | AJ31: 0 | AK31: 111732 | AL31: 0 | AM31: 9577 | AN31: 13000 | AO31: 0 | AW31: 316910 | AX31: 1279255 | AY31: 0
A32: 15.737.550-4 | B32: F1 | C32: Hurtado | D32: Canto | E32: Alejandro Eduardo | F32: Coordinador Senior | G32: OUTSOURCING, CODELCO CHILE -V. P., CODELCO CHILE -V. P. | H32: 100 | I32: 30 | J32: 42 | K32: 0 | L32: 3351652 | M32: 3351652 | N32: 2816982 | O32: 219115 | P32: 0 | Q32: 0 | R32: 0 | AB32: 100000 | AE32: 315555 | AF32: 100000 | AH32: 3551652 | AI32: 377731 | AJ32: 0 | AK32: 234616 | AL32: 16921 | AM32: 20110 | AN32: 91513 | AO32: 0 | AS32: 385837 | AW32: 1126728 | AX32: 2424924 | AY32: 0
A33: 18.467.232-4 | B33: F1 | C33: Jamis | D33: Matus | E33: Juan Ignacio | F33: Gerente de Clientes y Licitaciones | G33: Over Head, Administración, Comercial | H33: 1111 | I33: 30 | J33: 44 | K33: 0 | L33: 2860189 | M33: 2860189 | N33: 2641074 | O33: 219115 | P33: 0 | Q33: 0 | R33: 0 | AB33: 150000 | AF33: 150000 | AH33: 3160189 | AI33: 302608 | AJ33: 0 | AK33: 200213 | AL33: 0 | AM33: 17161 | AN33: 62547 | AO33: 0 | AQ33: 19800 | AW33: 602329 | AX33: 2557860 | AY33: 0
A34: 15.805.887-1 | B34: F1 | C34: Jara | D34: Ochoa | E34: Jacqueline Carolina | F34: Asesor Senior de Prevención de Riesgos | G34: OUTSOURCING, CODELCO, Modulo 2 | I34: 30 | J34: 42 | K34: 0 | L34: 2748807 | M34: 2748807 | N34: 2056359 | O34: 219115 | P34: 0 | Q34: 0 | R34: 0 | Y34: 125000 | AA34: 473333 | AB34: 250000 | AF34: 250000 | AH34: 3373807 | AI34: 309791 | AJ34: 0 | AK34: 192416 | AL34: 1080 | AM34: 16493 | AN34: 53653 | AO34: 0 | AS34: 186081 | AW34: 759514 | AX34: 2614293 | AY34: 0
A35: 13.462.122-2 | B35: F1 | C35: Labraña | D35: Gutierrez | E35: Maria Carolina | F35: Coordinador Experto | G35: OUTSOURCING, CODELCO CHILE -V. P., CODELCO CHILE -V. P. | H35: 100 | I35: 30 | J35: 42 | K35: 0 | L35: 3678639 | M35: 4263081 | N35: 3570633 | O35: 219115 | P35: 0 | Q35: 0 | R35: 0 | AB35: 100000 | AE35: 473333 | AF35: 100000 | AH35: 4463081 | AI35: 414583 | AJ35: 0 | AK35: 257505 | AL35: 1471 | AM35: 25578 | AN35: 160564 | AO35: 0 | AS35: 29854 | AW35: 889555 | AX35: 3573526 | AY35: 0
A36: 13.035.195-6 | B36: F1 | C36: La Roche | D36: Benitez | E36: Udo Franz | F36: ASSET OPTIMIZATION | G36: OUTSOURCING, Goldfields, Goldfield | H36: 100 | I36: 30 | J36: 40 | K36: 0 | L36: 3678639 | M36: 4328779 | N36: 4109664 | O36: 219115 | P36: 0 | Q36: 0 | R36: 0 | AH36: 4328779 | AI36: 414583 | AJ36: 0 | AK36: 257505 | AL36: 306471 | AM36: 25973 | AN36: 168443 | AO36: 0 | AW36: 1172975 | AX36: 3155804 | AY36: 0
A37: 20.465.683-5 | B37: F1 | C37: Morales | D37: Valdes | E37: Barbara Jesus | F37: Marketing Analyst | G37: OUTSOURCING, EDGEWELL CHILE, EDGEWELL CHILE | H37: 100 | I37: 21 | J37: 40 | K37: 0 | L37: 1615615 | M37: 1615615 | N37: 1396500 | O37: 219115 | P37: 0 | Q37: 0 | R37: 0 | S37: 7000 | U37: 14000 | AH37: 1636615 | AI37: 170932 | AJ37: 0 | AK37: 113093 | AL37: 21839 | AM37: 9694 | AN37: 13312 | AO37: 0 | AW37: 328870 | AX37: 1307745 | AY37: 0
A38: 16.163.207-4 | B38: F1 | C38: Morrison | D38: Robles | E38: Dawn Faye | F38: Asistente Comercial Bilingue | G38: Over Head, Administración, Comercial | H38: 1111 | I38: 30 | J38: 44 | K38: 0 | L38: 2586937 | M38: 2586937 | N38: 2367822 | O38: 219115 | P38: 0 | Q38: 0 | R38: 0 | AH38: 2586937 | AI38: 288702 | AJ38: 0 | AK38: 181086 | AL38: 408028 | AM38: 15522 | AN38: 42318 | AO38: 0 | AW38: 935656 | AX38: 1651281 | AY38: 0
A39: 15.475.910-7 | B39: F1 | C39: Muñoz | D39: Gonzalez | E39: Jocelyn Andrea | F39: Receptionist & Administrative Assistant | G39: OUTSOURCING, Endress Hauser, Endress Hauser | H39: 100 | I39: 3 | J39: 40 | K39: 0 | L39: 183941 | M39: 183941 | N39: 147153 | O39: 36788 | P39: 0 | Q39: 0 | R39: 0 | AH39: 183941 | AI39: 21043 | AJ39: 0 | AK39: 12876 | AL39: 0 | AM39: 1104 | AN39: 0 | AO39: 0 | AQ39: 29700 | AW39: 64723 | AX39: 119218 | AY39: 0
A40: 18.057.004-7 | B40: F1 | C40: Muñoz | D40: Matamala | E40: Denisse Ninoska | F40: SERVICE ASSISTANT | G40: OUTSOURCING, Endress Hauser, Endress Hauser | H40: 100 | I40: 30 | J40: 42 | K40: 0 | L40: 1700761 | M40: 1700761 | N40: 1481646 | O40: 219115 | P40: 0 | Q40: 0 | R40: 0 | AH40: 1700761 | AI40: 179941 | AJ40: 0 | AK40: 119053 | AL40: 0 | AM40: 10205 | AN40: 16972 | AO40: 0 | AW40: 326171 | AX40: 1374590 | AY40: 0
A41: 20.047.644-1 | B41: F1 | C41: Muñoz | D41: Muñoz | E41: Hernán Stefano | F41: Jefe de Administración y Control de Gestión | G41: Over Head, Administración, Comercial | H41: 1111 | I41: 30 | J41: 42 | K41: 0 | L41: 1235115 | M41: 1235115 | N41: 1016000 | O41: 219115 | P41: 0 | Q41: 0 | R41: 0 | Y41: 15000 | AB41: 50000 | AF41: 50000 | AH41: 1350115 | AI41: 129193 | AJ41: 0 | AK41: 86458 | AL41: 0 | AM41: 7411 | AN41: 1792 | AO41: 0 | AS41: 74207 | AU41: 50000 | AW41: 349061 | AX41: 1001054 | AY41: 0
...

Sheet EMPRESA DE SER...ORIOS G.A. SPA
A1: Libro: Remuneraciones
A2: Empresa: EMPRESA DE SERVICIOS TRANSITORIOS G.A. SPA (78.231.643-5)
A3: Periodo: Agosto 2026
A4: Fecha Generación: 28/08/2026 a las 02:47PM
A6: RUT | B6: CÓDIGO | C6: AP PATERNO | D6: AP MATERNO | E6: NOMBRES | F6: CARGO | G6: AREA | H6: CENTRO COSTO | I6: DÍAS TRABAJADOS | J6: HORAS SEMANALES | K6: HORAS NO TRABAJADAS | L6: BASE IMP. PREVISIÓN | M6: BASE IMP. CESANTÍA | N6: SUELDO BASE | O6: GRATIFICACIÓN | P6: APORTE ASISTENCIA | Q6: HORAS EXTRAS | R6: ASIGNACIÓN FAMILIAR | S6: ASIGNACIÓN POR TELETRABAJO | T6: ASIGNACIÓN SALA CUNA | U6: ASIGNACIÓN TELEFONÍA E INTERNET | V6: BONO | W6: BONO ESTUDIO | X6: BONO GESTIÓN | Y6: BONO INTERNET | Z6: BONO TELEFONIA | AA6: BONO TRIMESTRAL ACUERDO MARCO | AB6: COLACIÓN | AC6: COMISIONES | AD6: DIFERENCIA BONO | AE6: INCENTIVO TRIMESTRAL CUOTA 3 | AF6: MOVILIZACIÓN | AG6: VIATICO | AH6: TOTAL HABERES | AI6: PREVIS | AJ6: APV | AK6: SALUD | AL6: SALUD VOLUNTARIA | AM6: CESANTÍA | AN6: IMPUESTO | AO6: CUENTA_2 | AP6: ANTICIPO DE REMUNERACIONES | AQ6: CONVENIO FALP | AR6: CUENTA 2 PESOS | AS6: CRÉDITO PERSONAL CAJA LOS ANDES | AT6: PRESTAMO EMPRESA | AU6: PRÉSTAMO EMPRESA | AV6: SEGURO DE VIDA CAJA LOS ANDES | AW6: TOTAL DESCUENTOS | AX6: SUELDO LÍQUIDO | AY6: SOBREGIRO
A7: 20.162.327-8 | B7: F1 | C7: Charrie | D7: Troncoso | E7: Javiera Ignacia | F7: Key Account Executive | G7: OUTSOURCING, EDGEWELL CHILE, EDGEWELL CHILE | H7: 100 | I7: 30 | J7: 40 | K7: 0 | L7: 3157134 | M7: 3157134 | N7: 2338019 | O7: 219115 | P7: 0 | Q7: 0 | R7: 0 | S7: 10000 | V7: 600000 | Z7: 20000 | AF7: 220000 | AH7: 3407134 | AI7: 334025 | AJ7: 0 | AK7: 220999 | AL7: 0 | AM7: 0 | AN7: 83500 | AO7: 0 | AW7: 638524 | AX7: 2768610 | AY7: 0
A8: 20.722.232-1 | B8: F1 | C8: Nordin | D8: Campos | E8: Antonia Belen | F8: SALES ENABLEMENT REP SUPPORT | G8: GA EST, Endress Hauser, Endress Hauser | H8: 100 | I8: 30 | J8: 40 | K8: 0 | L8: 990000 | M8: 990000 | N8: 792000 | O8: 198000 | P8: 0 | Q8: 0 | R8: 0 | AH8: 990000 | AI8: 104742 | AJ8: 0 | AK8: 69300 | AL8: 0 | AM8: 0 | AN8: 0 | AO8: 0 | AW8: 174042 | AX8: 815958 | AY8: 0
A9: 26.591.232-k | B9: F1 | C9: Ortega | D9: Paredes | E9: Gabriela Mercedes | F9: Ejecutivo(a) Comercial | G9: GA EST, Schindler, Schindler | H9: 100 | I9: 30 | J9: 42 | K9: 0 | L9: 3041378 | M9: 3041378 | N9: 1000000 | O9: 219115 | P9: 0 | Q9: 0 | R9: 0 | AB9: 120000 | AC9: 1822263 | AF9: 60000 | AH9: 3221378 | AI9: 348238 | AJ9: 0 | AK9: 212896 | AL9: 0 | AM9: 0 | AN9: 73750 | AO9: 0 | AP9: 200000 | AW9: 834884 | AX9: 2386494 | AY9: 0
A10: 16.628.617-4 | B10: F1 | C10: Palma | D10: Campos | E10: Cecilia Tamara | F10: Receptionist & Administrative Assistant | G10: GA EST, Endress Hauser, Endress Hauser | H10: 100 | I10: 30 | J10: 40 | K10: 0 | L10: 1690647 | M10: 1690647 | N10: 1471532 | O10: 219115 | P10: 0 | Q10: 0 | R10: 0 | AH10: 1690647 | AI10: 178870 | AJ10: 0 | AK10: 118345 | AL10: 0 | AM10: 0 | AN10: 17047 | AO10: 0 | AW10: 314262 | AX10: 1376385 | AY10: 0
A11: 22.647.597-4 | B11: F1 | C11: Videla | D11: Lopez | E11: Josefa Alejandra | F11: Accounts Assistant | G11: GA EST, Endress Hauser, Endress Hauser | H11: 100 | I11: 30 | J11: 40 | K11: 0 | L11: 691941 | M11: 691941 | N11: 553553 | O11: 138388 | P11: 0 | Q11: 0 | R11: 0 | AH11: 691941 | AI11: 72377 | AJ11: 0 | AK11: 48436 | AL11: 0 | AM11: 0 | AN11: 0 | AO11: 0 | AW11: 120813 | AX11: 571128 | AY11: 0
AX13: =SUM(AX7:AX11) -> 7918575
